Workbook
Name Expenses: Analysis!$B$5
Name Profit: Analysis!$B$6
Name Revenue: Analysis!$B$4
Name Slicer_CustomerCity: #N/A
Name Slicer_CustomerName: #N/A
Name Slicer_Gender: #N/A
Name Slicer_ProductCategory: #N/A

Sheet Sheet1
A3: Row Labels | B3: Sum of SumOfProfit
A4: Older | B4: 5966911.8
A5: young | B5: 11244481
A6: Grand Total | B6: 17211393

Sheet Analysis
A2: Sales Peroformance
A3: Values
A4: Sum of Revenue | B4: 1.1474262e+08 | D4: Profit Margin
A5: Sum of Expenses | B5: 97531227 | D5: =Profit/Revenue -> 0.15 | E5: 34
A6: Sum of SumOfProfit | B6: 17211393
A10: Revenue By Weeks
A11: Row Labels | B11: Sum of Revenue
A12: 40 | B12: 5151515.9 | I12: Profit By Weeks
A13: 41 | B13: 8021415 | I13: Row Labels | J13: Sum of SumOfProfit
A14: 42 | B14: 9039991.4 | I14: 40 | J14: 772727.39
A15: 43 | B15: 8273426.1 | I15: 41 | J15: 1203212.3
A16: 44 | B16: 6483549.1 | I16: 42 | J16: 1355998.7
A17: 45 | B17: 8499907.5 | I17: 43 | J17: 1241013.9
A18: 46 | B18: 8029014.6 | I18: 44 | J18: 972532.37
A19: 47 | B19: 10935728 | I19: 45 | J19: 1274986.1
A20: 48 | B20: 8439774.2 | I20: 46 | J20: 1204352.2
A21: 49 | B21: 9654830.7 | I21: 47 | J21: 1640359.1
A22: 50 | B22: 8268639 | I22: 48 | J22: 1265966.1
A23: 51 | B23: 10436412 | I23: 49 | J23: 1448224.6
A24: 52 | B24: 8699909.7 | I24: 50 | J24: 1240295.8
A25: 53 | B25: 4808506.7 | I25: 51 | J25: 1565461.8
A26: Grand Total | B26: 1.1474262e+08 | I26: 52 | J26: 1304986.5
I27: 53 | J27: 721276
I28: Grand Total | J28: 17211393
A33: Row Labels | B33: Sum of SumOfProfit
A34: California | B34: 1762070.1 | D34: California | E34: 1762070.1
A35: Florida | B35: 3278135.8 | D35: Florida | E35: 3278135.8
A36: Georgia | B36: 1671271.9 | D36: Georgia | E36: 1671271.9
A37: Illinois | B37: 1510937.2 | D37: Illinois | E37: 1510937.2
A38: Texas | B38: 6097955 | D38: Texas | E38: 6097955
A39: Washington | B39: 2891023.1 | D39: Washington | E39: 2891023.1
A40: Grand Total | B40: 17211393
A56: Row Labels | B56: Sum of SumOfProfit
A57: TURTLE NECK | B57: 666102.8
A58: SNEAKERS | B58: 666560.64
A59: BADMINTON RACKET | B59: 670747.11
A60: MONOPOLY | B60: 684575.09
A61: TENNIS BAT | B61: 695271.35
A62: GYM GLOVES | B62: 705160.36
A63: GOLD RINGS | B63: 726596.22
...

Sheet Dashboarding

Sheet Orders
A1: OrderID | B1: OrderDate | C1: Week | D1: CustomerID | E1: ProductID | F1: Quantity | G1: Selling Price | H1: Cost Price | I1: Revenue | J1: Expenses | K1: SumOfProfit | L1: Salesperson | M1: CustomerCity | N1: CustomerName | O1: Gender | P1: Age | Q1: Age Category | R1: ProductName | S1: ProductCategory
A2: ORD-0000 | B2: 45989 | C2: =WEEKNUM(Orders[[#This Row],[OrderDate]]) -> 48 | D2: CUST-142 | E2: PROD-120 | F2: 10 | G2: 5816.9 | H2: 4944.365 | I2: =Orders[[#This Row],[Quantity]]*Orders[[#This Row],[Selling Price]] -> 58169 | J2: =Orders[[#This Row],[Quantity]]*Orders[[#This Row],[Cost Price]] -> 49443.65 | K2: =Orders[[#This Row],[Revenue]]-Orders[[#This Row],[Expenses]] -> 8725.35 | L2: Kayla | M2: =_xlfn.XLOOKUP(Orders[[#This Row],[CustomerID]],Customers[CustomerID],Customers[City]) -> Washington | N2: =_xlfn.XLOOKUP(Orders[[#This Row],[CustomerID]],Customers[CustomerID],Customers[CustomerName]) -> Bi si Bello | O2: =_xlfn.XLOOKUP(Orders[[#This Row],[CustomerID]],Customers[CustomerID],Customers[Gender]) -> Female | P2: =_xlfn.XLOOKUP(Orders[[#This Row],[CustomerID]],Customers[CustomerID],Customers[CustomerAge]) -> 38 | Q2: =IF(Orders[[#This Row],[Age]]>=35,"Older","Young") -> Older | R2: =_xlfn.XLOOKUP(Orders[[#This Row],[ProductID]],Products[ProductID],Products[ProductName]) -> BEADED EARRINGS AND NECKLACES | S2: =_xlfn.XLOOKUP(Orders[[#This Row],[ProductID]],Products!A:A,Products!C:C) -> Accessories
A3: ORD-0001 | B3: 45935 | C3: =WEEKNUM(Orders[[#This Row],[OrderDate]]) -> 41 | D3: CUST-056 | E3: PROD-112 | F3: 6 | G3: 8180.8 | H3: 6953.68 | I3: =Orders[[#This Row],[Quantity]]*Orders[[#This Row],[Selling Price]] -> 49084.8 | J3: =Orders[[#This Row],[Quantity]]*Orders[[#This Row],[Cost Price]] -> 41722.08 | K3: =Orders[[#This Row],[Revenue]]-Orders[[#This Row],[Expenses]] -> 7362.72 | L3: Brenda | M3: =_xlfn.XLOOKUP(Orders[[#This Row],[CustomerID]],Customers[CustomerID],Customers[City]) -> Texas | N3: =_xlfn.XLOOKUP(Orders[[#This Row],[CustomerID]],Customers[CustomerID],Customers[CustomerName]) -> Efe Ojo | O3: =_xlfn.XLOOKUP(Orders[[#This Row],[CustomerID]],Customers[CustomerID],Customers[Gender]) -> Female | P3: =_xlfn.XLOOKUP(Orders[[#This Row],[CustomerID]],Customers[CustomerID],Customers[CustomerAge]) -> 55 | Q3: =IF(Orders[[#This Row],[Age]]>=35,"older","young") -> older | R3: =_xlfn.XLOOKUP(Orders[[#This Row],[ProductID]],Products[ProductID],Products[ProductName]) -> BOUBOU | S3: =_xlfn.XLOOKUP(Orders[[#This Row],[ProductID]],Products!A:A,Products!C:C) -> Clothing
A4: ORD-0002 | B4: 46021 | C4: =WEEKNUM(Orders[[#This Row],[OrderDate]]) -> 53 | D4: CUST-095 | E4: PROD-131 | F4: 7 | G4: 5648.6 | H4: 4801.31 | I4: =Orders[[#This Row],[Quantity]]*Orders[[#This Row],[Selling Price]] -> 39540.2 | J4: =Orders[[#This Row],[Quantity]]*Orders[[#This Row],[Cost Price]] -> 33609.17 | K4: =Orders[[#This Row],[Revenue]]-Orders[[#This Row],[Expenses]] -> 5931.03 | L4: Cheyenne | M4: =_xlfn.XLOOKUP(Orders[[#This Row],[CustomerID]],Customers[CustomerID],Customers[City]) -> Texas | N4: =_xlfn.XLOOKUP(Orders[[#This Row],[CustomerID]],Customers[CustomerID],Customers[CustomerName]) -> Abiola Igwe | O4: =_xlfn.XLOOKUP(Orders[[#This Row],[CustomerID]],Customers[CustomerID],Customers[Gender]) -> Male | P4: =_xlfn.XLOOKUP(Orders[[#This Row],[CustomerID]],Customers[CustomerID],Customers[CustomerAge]) -> 39 | Q4: =IF(Orders[[#This Row],[Age]]>=35,"older","young") -> older | R4: =_xlfn.XLOOKUP(Orders[[#This Row],[ProductID]],Products[ProductID],Products[ProductName]) -> MONOPOLY | S4: =_xlfn.XLOOKUP(Orders[[#This Row],[ProductID]],Products!A:A,Products!C:C) -> Games
A5: ORD-0003 | B5: 45957 | C5: =WEEKNUM(Orders[[#This Row],[OrderDate]]) -> 44 | D5: CUST-092 | E5: PROD-120 | F5: 4 | G5: 15926.8 | H5: 13537.78 | I5: =Orders[[#This Row],[Quantity]]*Orders[[#This Row],[Selling Price]] -> 63707.2 | J5: =Orders[[#This Row],[Quantity]]*Orders[[#This Row],[Cost Price]] -> 54151.12 | K5: =Orders[[#This Row],[Revenue]]-Orders[[#This Row],[Expenses]] -> 9556.08 | L5: Joshua | M5: =_xlfn.XLOOKUP(Orders[[#This Row],[CustomerID]],Customers[CustomerID],Customers[City]) -> Illinois | N5: =_xlfn.XLOOKUP(Orders[[#This Row],[CustomerID]],Customers[CustomerID],Customers[CustomerName]) -> Bisi Adeyemi | O5: =_xlfn.XLOOKUP(Orders[[#This Row],[CustomerID]],Customers[CustomerID],Customers[Gender]) -> Female | P5: =_xlfn.XLOOKUP(Orders[[#This Row],[CustomerID]],Customers[CustomerID],Customers[CustomerAge]) -> 48 | Q5: =IF(Orders[[#This Row],[Age]]>=35,"older","young") -> older | R5: =_xlfn.XLOOKUP(Orders[[#This Row],[ProductID]],Products[ProductID],Products[ProductName]) -> BEADED EARRINGS AND NECKLACES | S5: =_xlfn.XLOOKUP(Orders[[#This Row],[ProductID]],Products!A:A,Products!C:C) -> Accessories
A6: ORD-0004 | B6: 46005 | C6: =WEEKNUM(Orders[[#This Row],[OrderDate]]) -> 51 | D6: CUST-030 | E6: PROD-105 | F6: 5 | G6: 19412.5 | H6: 16500.625 | I6: =Orders[[#This Row],[Quantity]]*Orders[[#This Row],[Selling Price]] -> 97062.5 | J6: =Orders[[#This Row],[Quantity]]*Orders[[#This Row],[Cost Price]] -> 82503.125 | K6: =Orders[[#This Row],[Revenue]]-Orders[[#This Row],[Expenses]] -> 14559.375 | L6: Douglas | M6: =_xlfn.XLOOKUP(Orders[[#This Row],[CustomerID]],Customers[CustomerID],Customers[City]) -> California | N6: =_xlfn.XLOOKUP(Orders[[#This Row],[CustomerID]],Customers[CustomerID],Customers[CustomerName]) -> Obi Adeyemi | O6: =_xlfn.XLOOKUP(Orders[[#This Row],[CustomerID]],Customers[CustomerID],Customers[Gender]) -> Male | P6: =_xlfn.XLOOKUP(Orders[[#This Row],[CustomerID]],Customers[CustomerID],Customers[CustomerAge]) -> 24 | Q6: =IF(Orders[[#This Row],[Age]]>=35,"older","young") -> young | R6: =_xlfn.XLOOKUP(Orders[[#This Row],[ProductID]],Products[ProductID],Products[ProductName]) -> GYM BAG | S6: =_xlfn.XLOOKUP(Orders[[#This Row],[ProductID]],Products!A:A,Products!C:C) -> Gym
A7: ORD-0005 | B7: 45990 | C7: =WEEKNUM(Orders[[#This Row],[OrderDate]]) -> 48 | D7: CUST-099 | E7: PROD-104 | F7: 5 | G7: 14778.1 | H7: 12561.385 | I7: =Orders[[#This Row],[Quantity]]*Orders[[#This Row],[Selling Price]] -> 73890.5 | J7: =Orders[[#This Row],[Quantity]]*Orders[[#This Row],[Cost Price]] -> 62806.925 | K7: =Orders[[#This Row],[Revenue]]-Orders[[#This Row],[Expenses]] -> 11083.575 | L7: Katie | M7: =_xlfn.XLOOKUP(Orders[[#This Row],[CustomerID]],Customers[CustomerID],Customers[City]) -> Texas | N7: =_xlfn.XLOOKUP(Orders[[#This Row],[CustomerID]],Customers[CustomerID],Customers[CustomerName]) -> Temi Bello | O7: =_xlfn.XLOOKUP(Orders[[#This Row],[CustomerID]],Customers[CustomerID],Customers[Gender]) -> Female | P7: =_xlfn.XLOOKUP(Orders[[#This Row],[CustomerID]],Customers[CustomerID],Customers[CustomerAge]) -> 52 | Q7: =IF(Orders[[#This Row],[Age]]>=35,"older","young") -> older | R7: =_xlfn.XLOOKUP(Orders[[#This Row],[ProductID]],Products[ProductID],Products[ProductName]) -> GYM GLOVES | S7: =_xlfn.XLOOKUP(Orders[[#This Row],[ProductID]],Products!A:A,Products!C:C) -> Gym | U7: =COUNTA(_xlfn.UNIQUE(E:E)) -> 36
A8: ORD-0006 | B8: 45968 | C8: =WEEKNUM(Orders[[#This Row],[OrderDate]]) -> 45 | D8: CUST-142 | E8: PROD-124 | F8: 9 | G8: 14335.3 | H8: 12185.005 | I8: =Orders[[#This Row],[Quantity]]*Orders[[#This Row],[Selling Price]] -> 129017.7 | J8: =Orders[[#This Row],[Quantity]]*Orders[[#This Row],[Cost Price]] -> 109665.04 | K8: =Orders[[#This Row],[Revenue]]-Orders[[#This Row],[Expenses]] -> 19352.655 | L8: David | M8: =_xlfn.XLOOKUP(Orders[[#This Row],[CustomerID]],Customers[CustomerID],Customers[City]) -> Washington | N8: =_xlfn.XLOOKUP(Orders[[#This Row],[CustomerID]],Customers[CustomerID],Customers[CustomerName]) -> Bi si Bello | O8: =_xlfn.XLOOKUP(Orders[[#This Row],[CustomerID]],Customers[CustomerID],Customers[Gender]) -> Female | P8: =_xlfn.XLOOKUP(Orders[[#This Row],[CustomerID]],Customers[CustomerID],Customers[CustomerAge]) -> 38 | Q8: =IF(Orders[[#This Row],[Age]]>=35,"older","young") -> older | R8: =_xlfn.XLOOKUP(Orders[[#This Row],[ProductID]],Products[ProductID],Products[ProductName]) -> GOLD RINGS | S8: =_xlfn.XLOOKUP(Orders[[#This Row],[ProductID]],Products!A:A,Products!C:C) -> Accessories
A9: ORD-0007 | B9: 45983 | C9: =WEEKNUM(Orders[[#This Row],[OrderDate]]) -> 47 | D9: CUST-071 | E9: PROD-106 | F9: 10 | G9: 11635.1 | H9: 9889.835 | I9: =Orders[[#This Row],[Quantity]]*Orders[[#This Row],[Selling Price]] -> 116351 | J9: =Orders[[#This Row],[Quantity]]*Orders[[#This Row],[Cost Price]] -> 98898.35 | K9: =Orders[[#This Row],[Revenue]]-Orders[[#This Row],[Expenses]] -> 17452.65 | L9: Jonathan | M9: =_xlfn.XLOOKUP(Orders[[#This Row],[CustomerID]],Customers[CustomerID],Customers[City]) -> Illinois | N9: =_xlfn.XLOOKUP(Orders[[#This Row],[CustomerID]],Customers[CustomerID],Customers[CustomerName]) -> Okon Ojo | O9: =_xlfn.XLOOKUP(Orders[[#This Row],[CustomerID]],Customers[CustomerID],Customers[Gender]) -> Male | P9: =_xlfn.XLOOKUP(Orders[[#This Row],[CustomerID]],Customers[CustomerID],Customers[CustomerAge]) -> 32 | Q9: =IF(Orders[[#This Row],[Age]]>=35,"older","young") -> young | R9: =_xlfn.XLOOKUP(Orders[[#This Row],[ProductID]],Products[ProductID],Products[ProductName]) -> SNEAKERS | S9: =_xlfn.XLOOKUP(Orders[[#This Row],[ProductID]],Products!A:A,Products!C:C) -> Sports
A10: ORD-0008 | B10: 46004 | C10: =WEEKNUM(Orders[[#This Row],[OrderDate]]) -> 50 | D10: CUST-043 | E10: PROD-134 | F10: 5 | G10: 11037.4 | H10: 9381.79 | I10: =Orders[[#This Row],[Quantity]]*Orders[[#This Row],[Selling Price]] -> 55187 | J10: =Orders[[#This Row],[Quantity]]*Orders[[#This Row],[Cost Price]] -> 46908.95 | K10: =Orders[[#This Row],[Revenue]]-Orders[[#This Row],[Expenses]] -> 8278.05 | L10: Ralph | M10: =_xlfn.XLOOKUP(Orders[[#This Row],[CustomerID]],Customers[CustomerID],Customers[City]) -> Florida | N10: =_xlfn.XLOOKUP(Orders[[#This Row],[CustomerID]],Customers[CustomerID],Customers[CustomerName]) -> Amina Danladi | O10: =_xlfn.XLOOKUP(Orders[[#This Row],[CustomerID]],Customers[CustomerID],Customers[Gender]) -> Female | P10: =_xlfn.XLOOKUP(Orders[[#This Row],[CustomerID]],Customers[CustomerID],Customers[CustomerAge]) -> 42 | Q10: =IF(Orders[[#This Row],[Age]]>=35,"older","young") -> older | R10: =_xlfn.XLOOKUP(Orders[[#This Row],[ProductID]],Products[ProductID],Products[ProductName]) -> KIDS GAMES | S10: =_xlfn.XLOOKUP(Orders[[#This Row],[ProductID]],Products!A:A,Products!C:C) -> Games
A11: ORD-0009 | B11: 45939 | C11: =WEEKNUM(Orders[[#This Row],[OrderDate]]) -> 41 | D11: CUST-052 | E11: PROD-121 | F11: 6 | G11: 13448.4 | H11: 11431.14 | I11: =Orders[[#This Row],[Quantity]]*Orders[[#This Row],[Selling Price]] -> 80690.4 | J11: =Orders[[#This Row],[Quantity]]*Orders[[#This Row],[Cost Price]] -> 68586.84 | K11: =Orders[[#This Row],[Revenue]]-Orders[[#This Row],[Expenses]] -> 12103.56 | L11: Daniel | M11: =_xlfn.XLOOKUP(Orders[[#This Row],[CustomerID]],Customers[CustomerID],Customers[City]) -> Texas | N11: =_xlfn.XLOOKUP(Orders[[#This Row],[CustomerID]],Customers[CustomerID],Customers[CustomerName]) -> Okon Balogun | O11: =_xlfn.XLOOKUP(Orders[[#This Row],[CustomerID]],Customers[CustomerID],Customers[Gender]) -> Male | P11: =_xlfn.XLOOKUP(Orders[[#This Row],[CustomerID]],Customers[CustomerID],Customers[CustomerAge]) -> 28 | Q11: =IF(Orders[[#This Row],[Age]]>=35,"older","young") -> young | R11: =_xlfn.XLOOKUP(Orders[[#This Row],[ProductID]],Products[ProductID],Products[ProductName]) -> GOLD BRACELETS | S11: =_xlfn.XLOOKUP(Orders[[#This Row],[ProductID]],Products!A:A,Products!C:C) -> Accessories
A12: ORD-0010 | B12: 46018 | C12: =WEEKNUM(Orders[[#This Row],[OrderDate]]) -> 52 | D12: CUST-019 | E12: PROD-126 | F12: 1 | G12: 1392.7 | H12: 1183.795 | I12: =Orders[[#This Row],[Quantity]]*Orders[[#This Row],[Selling Price]] -> 1392.7 | J12: =Orders[[#This Row],[Quantity]]*Orders[[#This Row],[Cost Price]] -> 1183.795 | K12: =Orders[[#This Row],[Revenue]]-Orders[[#This Row],[Expenses]] -> 208.905 | L12: Aaron | M12: =_xlfn.XLOOKUP(Orders[[#This Row],[CustomerID]],Customers[CustomerID],Customers[City]) -> California | N12: =_xlfn.XLOOKUP(Orders[[#This Row],[CustomerID]],Customers[CustomerID],Customers[CustomerName]) -> Jide Eze | O12: =_xlfn.XLOOKUP(Orders[[#This Row],[CustomerID]],Customers[CustomerID],Customers[Gender]) -> Male | P12: =_xlfn.XLOOKUP(Orders[[#This Row],[CustomerID]],Customers[CustomerID],Customers[CustomerAge]) -> 21 | Q12: =IF(Orders[[#This Row],[Age]]>=35,"older","young") -> young | R12: =_xlfn.XLOOKUP(Orders[[#This Row],[ProductID]],Products[ProductID],Products[ProductName]) -> IRON | S12: =_xlfn.XLOOKUP(Orders[[#This Row],[ProductID]],Products!A:A,Products!C:C) -> Electronics
A13: ORD-0011 | B13: 46007 | C13: =WEEKNUM(Orders[[#This Row],[OrderDate]]) -> 51 | D13: CUST-111 | E13: PROD-120 | F13: 1 | G13: 10759.3 | H13: 9145.405 | I13: =Orders[[#This Row],[Quantity]]*Orders[[#This Row],[Selling Price]] -> 10759.3 | J13: =Orders[[#This Row],[Quantity]]*Orders[[#This Row],[Cost Price]] -> 9145.405 | K13: =Orders[[#This Row],[Revenue]]-Orders[[#This Row],[Expenses]] -> 1613.895 | L13: Sean | M13: =_xlfn.XLOOKUP(Orders[[#This Row],[CustomerID]],Customers[CustomerID],Customers[City]) -> Florida | N13: =_xlfn.XLOOKUP(Orders[[#This Row],[CustomerID]],Customers[CustomerID],Customers[CustomerName]) -> Efe Adeyemi | O13: =_xlfn.XLOOKUP(Orders[[#This Row],[CustomerID]],Customers[CustomerID],Customers[Gender]) -> Female | P13: =_xlfn.XLOOKUP(Orders[[#This Row],[CustomerID]],Customers[CustomerID],Customers[CustomerAge]) -> 20 | Q13: =IF(Orders[[#This Row],[Age]]>=35,"older","young") -> young | R13: =_xlfn.XLOOKUP(Orders[[#This Row],[ProductID]],Products[ProductID],Products[ProductName]) -> BEADED EARRINGS AND NECKLACES | S13: =_xlfn.XLOOKUP(Orders[[#This Row],[ProductID]],Products!A:A,Products!C:C) -> Accessories
A14: ORD-0012 | B14: 45979 | C14: =WEEKNUM(Orders[[#This Row],[OrderDate]]) -> 47 | D14: CUST-112 | E14: PROD-124 | F14: 8 | G14: 5832.3 | H14: 4957.455 | I14: =Orders[[#This Row],[Quantity]]*Orders[[#This Row],[Selling Price]] -> 46658.4 | J14: =Orders[[#This Row],[Quantity]]*Orders[[#This Row],[Cost Price]] -> 39659.64 | K14: =Orders[[#This Row],[Revenue]]-Orders[[#This Row],[Expenses]] -> 6998.76 | L14: Andrea | M14: =_xlfn.XLOOKUP(Orders[[#This Row],[CustomerID]],Customers[CustomerID],Customers[City]) -> Texas | N14: =_xlfn.XLOOKUP(Orders[[#This Row],[CustomerID]],Customers[CustomerID],Customers[CustomerName]) -> Mustafa Balogun | O14: =_xlfn.XLOOKUP(Orders[[#This Row],[CustomerID]],Customers[CustomerID],Customers[Gender]) -> Male | P14: =_xlfn.XLOOKUP(Orders[[#This Row],[CustomerID]],Customers[CustomerID],Customers[CustomerAge]) -> 40 | Q14: =IF(Orders[[#This Row],[Age]]>=35,"older","young") -> older | R14: =_xlfn.XLOOKUP(Orders[[#This Row],[ProductID]],Products[ProductID],Products[ProductName]) -> GOLD RINGS | S14: =_xlfn.XLOOKUP(Orders[[#This Row],[ProductID]],Products!A:A,Products!C:C) -> Accessories
A15: ORD-0013 | B15: 46008 | C15: =WEEKNUM(Orders[[#This Row],[OrderDate]]) -> 51 | D15: CUST-141 | E15: PROD-121 | F15: 5 | G15: 19005.5 | H15: 16154.675 | I15: =Orders[[#This Row],[Quantity]]*Orders[[#This Row],[Selling Price]] -> 95027.5 | J15: =Orders[[#This Row],[Quantity]]*Orders[[#This Row],[Cost Price]] -> 80773.375 | K15: =Orders[[#This Row],[Revenue]]-Orders[[#This Row],[Expenses]] -> 14254.125 | L15: Anna | M15: =_xlfn.XLOOKUP(Orders[[#This Row],[CustomerID]],Customers[CustomerID],Customers[City]) -> Georgia | N15: =_xlfn.XLOOKUP(Orders[[#This Row],[CustomerID]],Customers[CustomerID],Customers[CustomerName]) -> Mustafa Danladi | O15: =_xlfn.XLOOKUP(Orders[[#This Row],[CustomerID]],Customers[CustomerID],Customers[Gender]) -> Male | P15: =_xlfn.XLOOKUP(Orders[[#This Row],[CustomerID]],Customers[CustomerID],Customers[CustomerAge]) -> 49 | Q15: =IF(Orders[[#This Row],[Age]]>=35,"older","young") -> older | R15: =_xlfn.XLOOKUP(Orders[[#This Row],[ProductID]],Products[ProductID],Products[ProductName]) -> GOLD BRACELETS | S15: =_xlfn.XLOOKUP(Orders[[#This Row],[ProductID]],Products!A:A,Products!C:C) -> Accessories
A16: ORD-0014 | B16: 45954 | C16: =WEEKNUM(Orders[[#This Row],[OrderDate]]) -> 43 | D16: CUST-096 | E16: PROD-115 | F16: 8 | G16: 5186.6 | H16: 4408.61 | I16: =Orders[[#This Row],[Quantity]]*Orders[[#This Row],[Selling Price]] -> 41492.8 | J16: =Orders[[#This Row],[Quantity]]*Orders[[#This Row],[Cost Price]] -> 35268.88 | K16: =Orders[[#This Row],[Revenue]]-Orders[[#This Row],[Expenses]] -> 6223.92 | L16: Kayla | M16: =_xlfn.XLOOKUP(Orders[[#This Row],[CustomerID]],Customers[CustomerID],Customers[City]) -> Florida | N16: =_xlfn.XLOOKUP(Orders[[#This Row],[CustomerID]],Customers[CustomerID],Customers[CustomerName]) -> Abiola Abubakar | O16: =_xlfn.XLOOKUP(Orders[[#This Row],[CustomerID]],Customers[CustomerID],Customers[Gender]) -> Male | P16: =_xlfn.XLOOKUP(Orders[[#This Row],[CustomerID]],Customers[CustomerID],Customers[CustomerAge]) -> 26 | Q16: =IF(Orders[[#This Row],[Age]]>=35,"older","young") -> young | R16: =_xlfn.XLOOKUP(Orders[[#This Row],[ProductID]],Products[ProductID],Products[ProductName]) -> TURTLE NECK | S16: =_xlfn.XLOOKUP(Orders[[#This Row],[ProductID]],Products!A:A,Products!C:C) -> Clothing
A17: ORD-0015 | B17: 46006 | C17: =WEEKNUM(Orders[[#This Row],[OrderDate]]) -> 51 | D17: CUST-083 | E17: PROD-134 | F17: 2 | G17: 14725.4 | H17: 12516.59 | I17: =Orders[[#This Row],[Quantity]]*Orders[[#This Row],[Selling Price]] -> 29450.8 | J17: =Orders[[#This Row],[Quantity]]*Orders[[#This Row],[Cost Price]] -> 25033.18 | K17: =Orders[[#This Row],[Revenue]]-Orders[[#This Row],[Expenses]] -> 4417.62 | L17: Jonathan | M17: =_xlfn.XLOOKUP(Orders[[#This Row],[CustomerID]],Customers[CustomerID],Customers[City]) -> California | N17: =_xlfn.XLOOKUP(Orders[[#This Row],[CustomerID]],Customers[CustomerID],Customers[CustomerName]) -> Mustafa Obi | O17: =_xlfn.XLOOKUP(Orders[[#This Row],[CustomerID]],Customers[CustomerID],Customers[Gender]) -> Male | P17: =_xlfn.XLOOKUP(Orders[[#This Row],[CustomerID]],Customers[CustomerID],Customers[CustomerAge]) -> 23 | Q17: =IF(Orders[[#This Row],[Age]]>=35,"older","young") -> young | R17: =_xlfn.XLOOKUP(Orders[[#This Row],[ProductID]],Products[ProductID],Products[ProductName]) -> KIDS GAMES | S17: =_xlfn.XLOOKUP(Orders[[#This Row],[ProductID]],Products!A:A,Products!C:C) -> Games
A18: ORD-0016 | B18: 45965 | C18: =WEEKNUM(Orders[[#This Row],[OrderDate]]) -> 45 | D18: CUST-051 | E18: PROD-120 | F18: 7 | G18: 18915.4 | H18: 16078.09 | I18: =Orders[[#This Row],[Quantity]]*Orders[[#This Row],[Selling Price]] -> 132407.8 | J18: =Orders[[#This Row],[Quantity]]*Orders[[#This Row],[Cost Price]] -> 112546.63 | K18: =Orders[[#This Row],[Revenue]]-Orders[[#This Row],[Expenses]] -> 19861.17 | L18: Thomas | M18: =_xlfn.XLOOKUP(Orders[[#This Row],[CustomerID]],Customers[CustomerID],Customers[City]) -> California | N18: =_xlfn.XLOOKUP(Orders[[#This Row],[CustomerID]],Customers[CustomerID],Customers[CustomerName]) -> Funke Danladi | O18: =_xlfn.XLOOKUP(Orders[[#This Row],[CustomerID]],Customers[CustomerID],Customers[Gender]) -> Female | P18: =_xlfn.XLOOKUP(Orders[[#This Row],[CustomerID]],Customers[CustomerID],Customers[CustomerAge]) -> 31 | Q18: =IF(Orders[[#This Row],[Age]]>=35,"older","young") -> young | R18: =_xlfn.XLOOKUP(Orders[[#This Row],[ProductID]],Products[ProductID],Products[ProductName]) -> BEADED EARRINGS AND NECKLACES | S18: =_xlfn.XLOOKUP(Orders[[#This Row],[ProductID]],Products!A:A,Products!C:C) -> Accessories
A19: ORD-0017 | B19: 45988 | C19: =WEEKNUM(Orders[[#This Row],[OrderDate]]) -> 48 | D19: CUST-090 | E19: PROD-122 | F19: 9 | G19: 12059.8 | H19: 10250.83 | I19: =Orders[[#This Row],[Quantity]]*Orders[[#This Row],[Selling Price]] -> 108538.2 | J19: =Orders[[#This Row],[Quantity]]*Orders[[#This Row],[Cost Price]] -> 92257.47 | K19: =Orders[[#This Row],[Revenue]]-Orders[[#This Row],[Expenses]] -> 16280.73 | L19: Sean | M19: =_xlfn.XLOOKUP(Orders[[#This Row],[CustomerID]],Customers[CustomerID],Customers[City]) -> Texas | N19: =_xlfn.XLOOKUP(Orders[[#This Row],[CustomerID]],Customers[CustomerID],Customers[CustomerName]) -> Folasade Ojo | O19: =_xlfn.XLOOKUP(Orders[[#This Row],[CustomerID]],Customers[CustomerID],Customers[Gender]) -> Female | P19: =_xlfn.XLOOKUP(Orders[[#This Row],[CustomerID]],Customers[CustomerID],Customers[CustomerAge]) -> 29 | Q19: =IF(Orders[[#This Row],[Age]]>=35,"older","young") -> young | R19: =_xlfn.XLOOKUP(Orders[[#This Row],[ProductID]],Products[ProductID],Products[ProductName]) -> SILVER BANGLES | S19: =_xlfn.XLOOKUP(Orders[[#This Row],[ProductID]],Products!A:A,Products!C:C) -> Accessories
... A2001: ORD-1999 | B2001: 45943 | C2001: =WEEKNUM(Orders[[#This Row],[OrderDate]]) -> 42 | D2001: CUST-117 | E2001: PROD-104 | F2001: 3 | G2001: 10317.5 | H2001: 8769.875 | I2001: =Orders[[#This Row],[Quantity]]*Orders[[#This Row],[Selling Price]] -> 30952.5 | J2001: =Orders[[#This Row],[Quantity]]*Orders[[#This Row],[Cost Price]] -> 26309.625 | K2001: =Orders[[#This Row],[Revenue]]-Orders[[#This Row],[Expenses]] -> 4642.875 | L2001: Ethan | M2001: =_xlfn.XLOOKUP(Orders[[#This Row],[CustomerID]],Customers[CustomerID],Customers[City]) -> Texas | N2001: =_xlfn.XLOOKUP(Orders[[#This Row],[CustomerID]],Customers[CustomerID],Customers[CustomerName]) -> Abiola Balogun | O2001: =_xlfn.XLOOKUP(Orders[[#This Row],[CustomerID]],Customers[CustomerID],Customers[Gender]) -> Male | P2001: =_xlfn.XLOOKUP(Orders[[#This Row],[CustomerID]],Customers[CustomerID],Customers[CustomerAge]) -> 29 | Q2001: =IF(Orders[[#This Row],[Age]]>=35,"older","young") -> young | R2001: =_xlfn.XLOOKUP(Orders[[#This Row],[ProductID]],Products[ProductID],Products[ProductName]) -> GYM GLOVES | S2001: =_xlfn.XLOOKUP(Orders[[#This Row],[ProductID]],Products!A:A,Products!C:C) -> Gym

Sheet Customers
A1: CustomerID | B1: CustomerName | C1: City | D1: Gender | E1: CustomerAge
A2: CUST-001 | B2: Sani Balogun | C2: California | D2: Male | E2: 27
A3: CUST-002 | B3: Okon Balogun | C3: Texas | D3: Male | E3: 20
A4: CUST-003 | B4: Efe Adeyemi | C4: Florida | D4: Female | E4: 25
A5: CUST-004 | B5: Chioma Eze | C5: Georgia | D5: Female | E5: 40
A6: CUST-005 | B6: Tunde Igwe | C6: Washington | D6: Male | E6: 20
A7: CUST-006 | B7: Jide Adeyemi | C7: Washington | D7: Male | E7: 19
A8: CUST-007 | B8: Blessing Eze | C8: Texas | D8: Female | E8: 44
A9: CUST-008 | B9: Amina Obi | C9: Florida | D9: Female | E9: 29
A10: CUST-009 | B10: Obi Bello | C10: Texas | D10: Male | E10: 18
A11: CUST-010 | B11: Jane Thomas | C11: Texas | D11: Male | E11: 21
A12: CUST-011 | B12: Uche Abubakar | C12: Illinois | D12: Male | E12: 18
A13: CUST-012 | B13: Sani Bello | C13: Washington | D13: Male | E13: 23
... A153: CUST-150 | B153: Ngozi Danladi | C153: Texas | D153: Female | E153: 25

Sheet Products
A1: ProductID | B1: ProductName | C1: Category
A2: PROD-101 | B2: YOGA MAT | C2: Gym
A3: PROD-102 | B3: CHEST EXPANDER | C3: Gym
A4: PROD-103 | B4: DUMB BELLS | C4: Gym
A5: PROD-104 | B5: GYM GLOVES | C5: Gym
A6: PROD-105 | B6: GYM BAG | C6: Gym
A7: PROD-106 | B7: SNEAKERS | C7: Sports
A8: PROD-107 | B8: BADMINTON RACKET | C8: Sports
A9: PROD-108 | B9: FOOTBALL | C9: Sports
A10: PROD-109 | B10: SKIPPING ROPE | C10: Sports
A11: PROD-110 | B11: TENNIS BAT | C11: Sports
A12: PROD-111 | B12: ANKARA | C12: Clothing
... A35: PROD-134 | B35: KIDS GAMES | C35: Games
